Workbook

Sheet LAMPIRAN I DONE
H1: Lampiran IV Keputusan Bersama Menteri
H2: Pendidikan dan Kebudayaan
H3: dan Kepala Badan Kepegawaian Negara
H4: Nomor : 4/VIII/PB/2014
H5: Nomor : 24 TAHUN 2014
H6: Tentang Ketentuan Pelaksanaan Peraturan Menteri Pendayagunaan Aparatur Negara Dan Reformasi Birokrasi Nomor 17 Tahun 2013 Tentang Jabatan Fungsional Dosen Dan Angka Kreditnya, Sebagaimana Telah Diubah Dengan Peraturan Menteri Pendayagunaan Aparatur Negara Dan Reformasi Birokrasi Republik Indonesia Nomor 46 Tahun 2013
A7: DAFTAR USUL PENETAPAN ANGKA KREDIT
A8: JABATAN AKADEMIK DOSEN
H10: MASA PENILAIAN :
H11: Bulan | I11: Januari | J11: Tahun | K11: 2012
H12: s.d. | O12: Petunjuk
H13: Bulan | I13: Juli | J13: Tahun | K13: 2023 | P13: : Kotak berwarna KUNING untuk diisi
B14: KETERANGAN PERORANGAN | P14: : Kotak berwarna HIJAU untuk dipilih sesuai pilihan yang ada
A15: 1 | B15: N a m a | F15: Dahliar Ananda | P15: : Kotak berwarna MERAH rumus, tidak perlu melakukan pengisian pada Kotak Merah
A16: 2 | B16: N I D N / N I P | F16: 0402058203 / 09820030 | P16: : Isilah Keterangan Perorangan terlebih dahulu, agar fungsi formula di tiap lampiran berfungsi
A17: 3 | B17: Nomor Seri Kartu Pegawai | F17: - | P17: : Apabila Keterangan Perorangan sudah diisi, maka otomatis akan mengisi nama pada tiap Lampiran berikutnya
A18: 4 | B18: Tempat dan Tanggal Lahir | F18: Banyuwangi, 2 Mei 1982 | P18: : Untuk nama Atasan / yang memberi pernyataan, diisi pada Lampiran II
A19: 5 | B19: Jenis Kelamin | F19: Laki-laki | P19: : Aplikasi Excel ini hanya bisa dioperasikan minimal pada Microsoft Excel 2010 s/d sekarang
A20: 6 | B20: Pendidikan yang diperhitungkan angka kreditnya | F20: Magister (S2) | O20: Created By : Nathaleo M. Apon. - Eugeniotejo
A21: 7 | B21: Jabatan Akademik Dosen/TMT | F21: Lektor | I21: 40848
A22: 8 | B22: Fakultas/Jurusan | F22: S1 Rekayasa Perangkat Lunak Kampus Surabaya Fakultas Informatika
A23: 9 | B23: Masa Kerja Lama
A24: 10 | B24: Masa Kerja Baru
A25: 11 | B25: Unit Kerja | F25: =IFERROR(VLOOKUP(F22,List!$C$2:$D$100,2,0),"") -> S1 Rekayasa Perangkat Lunak Kampus Surabaya Fakultas Informatika di Universitas Telkom pada LLDIKTI Wilayah IV Jawa Barat dan Banten
A26: II
A27: NO | B27: UNSUR YANG DINILAI
B28: UNSUR, SUB UNSUR & BUTIR KEGIATAN | H28: ANGKA KREDIT MENURUT
H29: INSTANSI PENGUSUL | K29: TIM PENILAI
H30: LAMA | I30: BARU | J30: JUMLAH | K30: LAMA | L30: BARU | M30: JUMLAH
A31: 1 | B31: 2 | H31: 3 | I31: 4 | J31: 5 | K31: 6 | L31: 7 | M31: 8
A32: I | B32: PENDIDIKAN
B33: A | C33: Pendidikan Formal
C34: 1 | D34: Sarjana (S1) | I34: =IF('LAMPIRAN II DONE'!J27="RUMUS","",'LAMPIRAN II DONE'!J27) -> 100 | J34: =IF(I34=0,"",I34) -> 100
C35: 2 | D35: Magister (S2) | I35: =IF('LAMPIRAN II DONE'!J28="RUMUS","",'LAMPIRAN II DONE'!J28) -> 50 | J35: =IF(I35=0,"",I35) -> 50
C36: 2 | D36: Doktor (S3) | I36: =IF('LAMPIRAN II DONE'!J29="RUMUS","",'LAMPIRAN II DONE'!J29) -> 50 | J36: =IF(I36=0,"",I36) -> 50
B37: B | C37: Pendidikan & Pelatihan Prajabatan
D38: Pendidikan & Pelatihan Prajabatan Golongan III | I38: =IF('LAMPIRAN II DONE'!G34=0,"",'LAMPIRAN II DONE'!G34) | J38: =IF(I38=0,"",I38)
A39: II | B39: PELAKSANAAN PENDIDIKAN
B40: A | C40: Melaksanakan Perkulihan/Tutorial & Membimbing, Menguji Serta Menyelenggarakan Pendidikan di Laboratorium, Praktek Keguruan Bengkel/Studio/Kebun Percobaan/Teknologi Pengajaran & Praktek Lapangan
D41: Melaksanakan Perkulihan/Tutorial & Membimbing, Menguji Serta Menyelenggarakan Pendidikan di Laboratorium, Praktik Keguruan Bengkel/Studio/Kebun Pada Fakultas/Sekolah Tinggi/Akademi/ Politeknik Sendiri, Pada Fakultas Lain Dalam Lingkungan Universitas/Institut Sendiri, maupun di Luar Perguruan Tinggi Sendiri Secara Melembaga Paling Banyak 12 SKS/Semester | I41: =IF('LAMPIRAN II DONE'!$G$206=0,"",'LAMPIRAN II DONE'!$G$206) -> 209 | J41: =IF(I41=0,"",I41) -> 209
...

Sheet LAMPIRAN II DONE
G1: Lampiran V Keputusan Bersama Menteri | U1: a.Rektor
G2: Pendidikan dan Kebudayaan | U2: b.Pembantu rektor/dekan/direktur program pasca sarjana
G3: dan Kepala Badan Kepegawaian Negara | U3: c.Ketua sekolah tinggi/pembantu dekan/asisten direktur program pasca sarjana/direktur politeknik
G4: Nomor : 4/VIII/PB/2014 | U4: d.Pembantu ketua sekolah tinggi/pembantu direktur politeknik
G5: Nomor : 24 TAHUN 2014 | U5: e.Direktur akademi
G6: Tentang Ketentuan Pelaksanaan Peraturan Menteri Pendayagunaan Aparatur Negara Dan Reformasi Birokrasi Nomor 17 Tahun 2013 Tentang Jabatan Fungsional Dosen Dan Angka Kreditnya, Sebagaimana Telah Diubah Dengan Peraturan Menteri Pendayagunaan Aparatur Negara Dan Reformasi Birokrasi Republik Indonesia Nomor 46 Tahun 2013 | U6: f.Pembantu direktur akademi/ketua jurusan/bagian pada universitas/institut/sekolah tinggi
U7: g.Ketua jurusan pada politeknik/akademi/sekretaris jurusan/bagian pada universitas/institu/sekolah tinggi
A8: SURAT PERNYATAAN | U8: h.Sekretaris jurusan pada politeknik/akademi dan kepala laboratorium universitas/institut/sekolah tinggi/politeknik/akademi
A9: MELAKSANAKAN KEGIATAN PENDIDIKAN DAN PENGAJARAN
A10: Yang bertanda tangan di bawah ini:
A11: 1 | B11: N a m a
A12: 2 | B12: N I P
A13: 3 | B13: Pangkat/Golongan Ruang
A14: 4 | B14: Jabatan Fungsional
A15: 5 | B15: Unit Kerja
A16: Menyatakan Bahwa
A17: 1 | B17: N a m a | C17: =IF('LAMPIRAN I DONE'!F15<>"",'LAMPIRAN I DONE'!F15,"") -> Dahliar Ananda
A18: 2 | B18: N I P | C18: =IF('LAMPIRAN I DONE'!F16<>"",'LAMPIRAN I DONE'!F16,"") -> 0402058203 / 09820030
A19: 3 | B19: Pangkat/Golongan Ruang | C19: - | I19: Petunjuk
A20: 4 | B20: Jabatan Fungsional | C20: =IF('LAMPIRAN I DONE'!F21<>"",'LAMPIRAN I DONE'!F21,"") -> Lektor | J20: : Kotak berwarna KUNING untuk diisi (khusus profil atasan/yang memberi pernyataan)
A21: 5 | B21: Unit Kerja | C21: =IF('LAMPIRAN I DONE'!F25<>"",'LAMPIRAN I DONE'!F25,"") -> S1 Rekayasa Perangkat Lunak Kampus Surabaya Fakultas Informatika di Universitas Telkom pada LLDIKTI Wilayah IV Jawa Barat dan Banten | J21: : Kotak berwarna HIJAU untuk dipilih sesuai pilihan yang ada
A22: Telah Melakukan Kegiatan Pendidikan dan Pengajaran Sebagai Berikut | J22: : Kotak berwarna MERAH rumus
A23: NO | B23: URAIAN KEGIATAN | C23: TANGGAL | D23: SATUAN HASIL | E23: JUMLAH VOLUME KEGIATAN | F23: ANGKA KREDIT | G23: JUMLAH ANGKA KREDIT | H23: KETERANGAN / BUKTI FISIK | J23: Untuk Row yang tidak diisi / dilewat mohon dihide Created By : Nathaleo M. Apon.
A24: 1 | B24: 2 | C24: 3 | D24: 4 | G24: 5 | H24: 6
A25: I | B25: Pendidikan
A26: A | B26: Pendidikan Formal
A27: 1 | B27: Pendidikan S1 | C27: - | D27: =IF(G27<>"rumus","Ijazah","") -> Ijazah | E27: =IF(I27<>"",1,"") -> 1 | F27: =IF(I27<>"",J27,"") -> 100 | G27: =IF(J27<>"rumus","1 x "&J27&" = "&J27,"rumus") -> 1 x 100 = 100 | H27: - | I27: Sarjana (S1) | J27: =IF(I27<>"",IF(I27="Doktor (S3) linier",50,IF(I27="Doktor (S3) non linier",15,IF(I27="Magister (S2) linier",50,IF(I27="Magister (S2) non linier",15,IF(I27="Sarjana (S1)",100,""))))),"rumus") -> 100
A28: 2 | B28: Pendidikan S2 | C28: - | D28: =IF(G28<>"rumus","Ijazah","") -> Ijazah | E28: =IF(I28<>"",1,"") -> 1 | F28: =IF(I28<>"",J28,"") -> 50 | G28: =IF(J28<>"rumus","1 x "&J28&" = "&J28,"rumus") -> 1 x 50 = 50 | H28: - | I28: Magister (S2) linier | J28: =IF(I28<>"",IF(I28="Doktor (S3) linier",50,IF(I28="Doktor (S3) non linier",15,IF(I28="Magister (S2) linier",50,IF(I28="Magister (S2) non linier",15,IF(I28="Sarjana (S1)",100,""))))),"rumus") -> 50
A29: 3 | B29: Pendidikan S3 | C29: - | D29: =IF(G29<>"rumus","Ijazah","") -> Ijazah | E29: =IF(I29<>"",1,"") -> 1 | F29: =IF(I29<>"",J29,"") -> 50 | G29: =IF(J29<>"rumus","1 x "&J29&" = "&J29,"rumus") -> 1 x 50 = 50 | H29: - | I29: Doktor (S3) linier | J29: =IF(I29<>"",IF(I29="Doktor (S3) linier",50,IF(I29="Doktor (S3) non linier",15,IF(I29="Magister (S2) linier",50,IF(I29="Magister (S2) non linier",15,IF(I29="Sarjana (S1)",100,""))))),"rumus") -> 50
B30: Jumlah | G30: =K30 -> 200 | K30: =SUM(J27:J29) -> 200
A31: B | B31: Diklat Pra Jabatan
A32: 1 | B32: Diklat Pra Jabatan | C32: - | D32: - | E32: =IF(I32<>"",1,"") | F32: =IF(I32<>"",J32,"") | G32: =IF(J32<>"rumus","1 x "&J32&" = "&J32,"rumus") -> rumus | H32: - | J32: =IF(I32="Diklat Pra Jabatan setiap Sertifikat",2,"rumus") -> rumus
A33: 2 | B33: Diklat Pra Jabatan | C33: - | D33: - | E33: =IF(I33<>"",1,"") | F33: =IF(I33<>"",J33,"") | G33: =IF(J33<>"rumus","1 x "&J33&" = "&J33,"rumus") -> rumus | H33: - | J33: =IF(I33="Diklat Pra Jabatan setiap Sertifikat",2,"rumus") -> rumus
B34: Jumlah | G34: =K34 -> 0 | K34: =SUM(J32:J33) -> 0
B35: Jumlah I | G35: =G30+G34 -> 200
A36: II | B36: Pelaksanaan Pendidikan
A37: A | B37: Melaksanakan perkuliahan | I37: sks | J37: kelas | K37: Akumulasi | L37: HPS
B38: ="a. Semester Gasal "&IF(C39<>"",C39,"")&" :" -> a. Semester Gasal 2012/2013 : | I38: =IF(I39<>"",0,"") -> 0 | J38: =IF(J39<>"",0,"") -> 0
A39: 1 | B39: KA1024 Algoritma dan Pemrograman, 4sks, 2kls | C39: 2012/2013 | D39: =IF(G39<>"rumus","SKS","") -> SKS | E39: =IF(K39<>"rumus",(IF(OR(AND(L39="sks>10",L38="sks<=10",IFERROR(SUMPRODUCT($I$38:I38,$J$38:J38)<10,FALSE)),AND(L39="sks>10",L38="")),(((10-SUMPRODUCT($I$38:I38,$J$38:J38))&" x "&1)&" "&(((I39*J39)-(10-SUMPRODUCT($I$38:I38,$J$38:J38)))&" x "&1)),(I39&" x "&J39))),"") -> 4 x 2 | F39: =IF(K39<>"rumus",(IF(OR(AND(L39="sks>10",L38="sks<=10",IFERROR(SUMPRODUCT($I$38:I38,$J$38:J38)<10,FALSE)),AND(L39="sks>10",L38="")),((IF('LAMPIRAN I DONE'!$F$21="Tenaga Pengajar",0.5,IF(OR('LAMPIRAN I DONE'!$F$21="Asisten Ahli",'LAMPIRAN I DONE'!$F$21="Lektor",'LAMPIRAN I DONE'!$F$21="Lektor Kepala",'LAMPIRAN I DONE'!$F$21="Guru Besar"),1,"")))&" "&(IF('LAMPIRAN I DONE'!$F$21="Tenaga Pengajar",0.25,IF(OR('LAMPIRAN I DONE'!$F$21="Asisten Ahli",'LAMPIRAN I DONE'!$F$21="Lektor",'LAMPIRAN I DONE'!$F$21="Lektor Kepala",'LAMPIRAN I DONE'!$F$21="Guru Besar"),0.5,"")))),((IF(OR(AND(L39="sks>10",L38="sks>10"),AND(L39="sks>10",L38="sks<=10")),IF('LAMPIRAN I DONE'!$F$21="Tenaga Pengajar",0.25,IF(OR('LAMPIRAN I DONE'!$F$21="Asisten Ahli",'LAMPIRAN I DONE'!$F$21="Lektor",'LAMPIRAN I DONE'!$F$21="Lektor Kepala",'LAMPIRAN I DONE'!$F$21="Guru Besar"),0.5,"")),IF('LAMPIRAN I DONE'!$F$21="Tenaga Pengajar",0.5,IF(OR('LAMPIRAN I DONE'!$F$21="Asisten Ahli",'LAMPIRAN I DONE'!$F$21="Lektor",'LAMPIRAN I DONE'!$F$21="Lektor Kepala",'LAMPIRAN I DONE'!$F$21="Guru Besar"),1,""))))))),"") -> 1 | G39: =IF(K39<>"rumus",(IF(OR(AND(L39="sks>10",L38="sks<=10",IFERROR(SUMPRODUCT($I$38:I38,$J$38:J38)<10,FALSE)),AND(L39="sks>10",L38="")),(((10-SUMPRODUCT($I$38:I38,$J$38:J38))&" x "&1&" x "&IF('LAMPIRAN I DONE'!$F$21="Tenaga Pengajar",0.5,IF(OR('LAMPIRAN I DONE'!$F$21="Asisten Ahli",'LAMPIRAN I DONE'!$F$21="Lektor",'LAMPIRAN I DONE'!$F$21="Lektor Kepala",'LAMPIRAN I DONE'!$F$21="Guru Besar"),1,""))&" = "&((10-SUMPRODUCT($I$38:I38,$J$38:J38))*IF('LAMPIRAN I DONE'!$F$21="Tenaga Pengajar",0.5,IF(OR('LAMPIRAN I DONE'!$F$21="Asisten Ahli",'LAMPIRAN I DONE'!$F$21="Lektor",'LAMPIRAN I DONE'!$F$21="Lektor Kepala",'LAMPIRAN I DONE'!$F$21="Guru Besar"),1,""))))&" "&(((I39*J39)-(10-SUMPRODUCT($I$38:I38,$J$38:J38)))&" x "&1&" x "&IF('LAMPIRAN I DONE'!$F$21="Tenaga Pengajar",0.25,IF(OR('LAMPIRAN I DONE'!$F$21="Asisten Ahli",'LAMPIRAN I DONE'!$F$21="Lektor",'LAMPIRAN I DONE'!$F$21="Lektor Kepala",'LAMPIRAN I DONE'!$F$21="Guru Besar"),0.5,""))&" = "&(((I39*J39)-(10-SUMPRODUCT($I$38:I38,$J$38:J38)))*IF('LAMPIRAN I DONE'!$F$21="Tenaga Pengajar",0.25,IF(OR('LAMPIRAN I DONE'!$F$21="Asisten Ahli",'LAMPIRAN I DONE'!$F$21="Lektor",'LAMPIRAN I DONE'!$F$21="Lektor Kepala",'LAMPIRAN I DONE'!$F$21="Guru Besar"),0.5,""))))),(I39&" x "&J39&" x "&(IF(OR(AND(L39="sks>10",L38="sks>10"),AND(L39="sks>10",L38="sks<=10")),IF('LAMPIRAN I DONE'!$F$21="Tenaga Pengajar",0.25,IF(OR('LAMPIRAN I DONE'!$F$21="Asisten Ahli",'LAMPIRAN I DONE'!$F$21="Lektor",'LAMPIRAN I DONE'!$F$21="Lektor Kepala",'LAMPIRAN I DONE'!$F$21="Guru Besar"),0.5,"")),IF('LAMPIRAN I DONE'!$F$21="Tenaga Pengajar",0.5,IF(OR('LAMPIRAN I DONE'!$F$21="Asisten Ahli",'LAMPIRAN I DONE'!$F$21="Lektor",'LAMPIRAN I DONE'!$F$21="Lektor Kepala",'LAMPIRAN I DONE'!$F$21="Guru Besar"),1,""))))&" = "&K39))),"rumus") -> 4 x 2 x 1 = 8 | H39: NOMOR : KEP. 039/ACD.11/1.0.0/2012 | I39: 4 | J39: 2 | K39: =IF(AND(I39<>"",J39<>""),(IF(OR(AND(L39="sks>10",L38="sks<=10",IFERROR(SUMPRODUCT($I$38:I38,$J$38:J38)<10,FALSE)),AND(L39="sks>10",L38="")),(((10-SUMPRODUCT($I$38:I38,$J$38:J38))*IF('LAMPIRAN I DONE'!$F$21="Tenaga Pengajar",0.5,IF(OR('LAMPIRAN I DONE'!$F$21="Asisten Ahli",'LAMPIRAN I DONE'!$F$21="Lektor",'LAMPIRAN I DONE'!$F$21="Lektor Kepala",'LAMPIRAN I DONE'!$F$21="Guru Besar"),1,"")))+(((I39*J39)-(10-SUMPRODUCT($I$38:I38,$J$38:J38)))*IF('LAMPIRAN I DONE'!$F$21="Tenaga Pengajar",0.25,IF(OR('LAMPIRAN I DONE'!$F$21="Asisten Ahli",'LAMPIRAN I DONE'!$F$21="Lektor",'LAMPIRAN I DONE'!$F$21="Lektor Kepala",'LAMPIRAN I DONE'!$F$21="Guru Besar"),0.5,"")))),IF(OR(AND(L39="sks>10",L38="sks>10"),AND(L39="sks>10",L38="sks<=10")),I39*J39*IF('LAMPIRAN I DONE'!$F$21="Tenaga Pengajar",0.25,IF(OR('LAMPIRAN I DONE'!$F$21="Asisten Ahli",'LAMPIRAN I DONE'!$F$21="Lektor",'LAMPIRAN I DONE'!$F$21="Lektor Kepala",'LAMPIRAN I DONE'!$F$21="Guru Besar"),0.5,"")),I39*J39*IF('LAMPIRAN I DONE'!$F$21="Tenaga Pengajar",0.5,IF(OR('LAMPIRAN I DONE'!$F$21="Asisten Ahli",'LAMPIRAN I DONE'!$F$21="Lektor",'LAMPIRAN I DONE'!$F$21="Lektor Kepala",'LAMPIRAN I DONE'!$F$21="Guru Besar"),1,""))))),"rumus") -> 8 | L39: =IF(AND(I39<>"",J39<>""),(IF(SUMPRODUCT($I$39:I39,$J$39:J39)<=10,"SKS<=10",IF(SUMPRODUCT($I$39:I39,$J$39:J39)>10,"SKS>10",""))),"rumus") -> SKS<=10
A40: 2 | B40: nama mk, sks, kls | C40: 2012/2013 | D40: =IF(G40<>"rumus","SKS","") | E40: =IF(K40<>"rumus",(IF(OR(AND(L40="sks>10",L39="sks<=10",IFERROR(SUMPRODUCT($I$38:I39,$J$38:J39)<10,FALSE)),AND(L40="sks>10",L39="")),(((10-SUMPRODUCT($I$38:I39,$J$38:J39))&" x "&1)&" "&(((I40*J40)-(10-SUMPRODUCT($I$38:I39,$J$38:J39)))&" x "&1)),(I40&" x "&J40))),"") | F40: =IF(K40<>"rumus",(IF(OR(AND(L40="sks>10",L39="sks<=10",IFERROR(SUMPRODUCT($I$38:I39,$J$38:J39)<10,FALSE)),AND(L40="sks>10",L39="")),((IF('LAMPIRAN I DONE'!$F$21="Tenaga Pengajar",0.5,IF(OR('LAMPIRAN I DONE'!$F$21="Asisten Ahli",'LAMPIRAN I DONE'!$F$21="Lektor",'LAMPIRAN I DONE'!$F$21="Lektor Kepala",'LAMPIRAN I DONE'!$F$21="Guru Besar"),1,"")))&" "&(IF('LAMPIRAN I DONE'!$F$21="Tenaga Pengajar",0.25,IF(OR('LAMPIRAN I DONE'!$F$21="Asisten Ahli",'LAMPIRAN I DONE'!$F$21="Lektor",'LAMPIRAN I DONE'!$F$21="Lektor Kepala",'LAMPIRAN I DONE'!$F$21="Guru Besar"),0.5,"")))),((IF(OR(AND(L40="sks>10",L39="sks>10"),AND(L40="sks>10",L39="sks<=10")),IF('LAMPIRAN I DONE'!$F$21="Tenaga Pengajar",0.25,IF(OR('LAMPIRAN I DONE'!$F$21="Asisten Ahli",'LAMPIRAN I DONE'!$F$21="Lektor",'LAMPIRAN I DONE'!$F$21="Lektor Kepala",'LAMPIRAN I DONE'!$F$21="Guru Besar"),0.5,"")),IF('LAMPIRAN I DONE'!$F$21="Tenaga Pengajar",0.5,IF(OR('LAMPIRAN I DONE'!$F$21="Asisten Ahli",'LAMPIRAN I DONE'!$F$21="Lektor",'LAMPIRAN I DONE'!$F$21="Lektor Kepala",'LAMPIRAN I DONE'!$F$21="Guru Besar"),1,""))))))),"") | G40: =IF(K40<>"rumus",(IF(OR(AND(L40="sks>10",L39="sks<=10",IFERROR(SUMPRODUCT($I$38:I39,$J$38:J39)<10,FALSE)),AND(L40="sks>10",L39="")),(((10-SUMPRODUCT($I$38:I39,$J$38:J39))&" x "&1&" x "&IF('LAMPIRAN I DONE'!$F$21="Tenaga Pengajar",0.5,IF(OR('LAMPIRAN I DONE'!$F$21="Asisten Ahli",'LAMPIRAN I DONE'!$F$21="Lektor",'LAMPIRAN I DONE'!$F$21="Lektor Kepala",'LAMPIRAN I DONE'!$F$21="Guru Besar"),1,""))&" = "&((10-SUMPRODUCT($I$38:I39,$J$38:J39))*IF('LAMPIRAN I DONE'!$F$21="Tenaga Pengajar",0.5,IF(OR('LAMPIRAN I DONE'!$F$21="Asisten Ahli",'LAMPIRAN I DONE'!$F$21="Lektor",'LAMPIRAN I DONE'!$F$21="Lektor Kepala",'LAMPIRAN I DONE'!$F$21="Guru Besar"),1,""))))&" "&(((I40*J40)-(10-SUMPRODUCT($I$38:I39,$J$38:J39)))&" x "&1&" x "&IF('LAMPIRAN I DONE'!$F$21="Tenaga Pengajar",0.25,IF(OR('LAMPIRAN I DONE'!$F$21="Asisten Ahli",'LAMPIRAN I DONE'!$F$21="Lektor",'LAMPIRAN I DONE'!$F$21="Lektor Kepala",'LAMPIRAN I DONE'!$F$21="Guru Besar"),0.5,""))&" = "&(((I40*J40)-(10-SUMPRODUCT($I$38:I39,$J$38:J39)))*IF('LAMPIRAN I DONE'!$F$21="Tenaga Pengajar",0.25,IF(OR('LAMPIRAN I DONE'!$F$21="Asisten Ahli",'LAMPIRAN I DONE'!$F$21="Lektor",'LAMPIRAN I DONE'!$F$21="Lektor Kepala",'LAMPIRAN I DONE'!$F$21="Guru Besar"),0.5,""))))),(I40&" x "&J40&" x "&(IF(OR(AND(L40="sks>10",L39="sks>10"),AND(L40="sks>10",L39="sks<=10")),IF('LAMPIRAN I DONE'!$F$21="Tenaga Pengajar",0.25,IF(OR('LAMPIRAN I DONE'!$F$21="Asisten Ahli",'LAMPIRAN I DONE'!$F$21="Lektor",'LAMPIRAN I DONE'!$F$21="Lektor Kepala",'LAMPIRAN I DONE'!$F$21="Guru Besar"),0.5,"")),IF('LAMPIRAN I DONE'!$F$21="Tenaga Pengajar",0.5,IF(OR('LAMPIRAN I DONE'!$F$21="Asisten Ahli",'LAMPIRAN I DONE'!$F$21="Lektor",'LAMPIRAN I DONE'!$F$21="Lektor Kepala",'LAMPIRAN I DONE'!$F$21="Guru Besar"),1,""))))&" = "&K40))),"rumus") -> rumus | H40: ( Isikan Nomor SK dengan lengkap) | K40: =IF(AND(I40<>"",J40<>""),(IF(OR(AND(L40="sks>10",L39="sks<=10",IFERROR(SUMPRODUCT($I$38:I39,$J$38:J39)<10,FALSE)),AND(L40="sks>10",L39="")),(((10-SUMPRODUCT($I$38:I39,$J$38:J39))*IF('LAMPIRAN I DONE'!$F$21="Tenaga Pengajar",0.5,IF(OR('LAMPIRAN I DONE'!$F$21="Asisten Ahli",'LAMPIRAN I DONE'!$F$21="Lektor",'LAMPIRAN I DONE'!$F$21="Lektor Kepala",'LAMPIRAN I DONE'!$F$21="Guru Besar"),1,"")))+(((I40*J40)-(10-SUMPRODUCT($I$38:I39,$J$38:J39)))*IF('LAMPIRAN I DONE'!$F$21="Tenaga Pengajar",0.25,IF(OR('LAMPIRAN I DONE'!$F$21="Asisten Ahli",'LAMPIRAN I DONE'!$F$21="Lektor",'LAMPIRAN I DONE'!$F$21="Lektor Kepala",'LAMPIRAN I DONE'!$F$21="Guru Besar"),0.5,"")))),IF(OR(AND(L40="sks>10",L39="sks>10"),AND(L40="sks>10",L39="sks<=10")),I40*J40*IF('LAMPIRAN I DONE'!$F$21="Tenaga Pengajar",0.25,IF(OR('LAMPIRAN I DONE'!$F$21="Asisten Ahli",'LAMPIRAN I DONE'!$F$21="Lektor",'LAMPIRAN I DONE'!$F$21="Lektor Kepala",'LAMPIRAN I DONE'!$F$21="Guru Besar"),0.5,"")),I40*J40*IF('LAMPIRAN I DONE'!$F$21="Tenaga Pengajar",0.5,IF(OR('LAMPIRAN I DONE'!$F$21="Asisten Ahli",'LAMPIRAN I DONE'!$F$21="Lektor",'LAMPIRAN I DONE'!$F$21="Lektor Kepala",'LAMPIRAN I DONE'!$F$21="Guru Besar"),1,""))))),"rumus") -> rumus | L40: =IF(AND(I40<>"",J40<>""),(IF(SUMPRODUCT($I$39:I40,$J$39:J40)<=10,"SKS<=10",IF(SUMPRODUCT($I$39:I40,$J$39:J40)>10,"SKS>10",""))),"rumus") -> rumus
...

Sheet LAMPIRAN III DONE
I1: Lampiran VI Keputusan Bersama Menteri | V1: 1).a).Hasil penelitian atau hasil pemikiran yang DIPUBLIKASIKAN dalam bentuk BUKU MONOGRAF
I2: Pendidikan dan Kebudayaan | V2: 1).b).Hasil penelitian atau hasil pemikiran yang DIPUBLIKASIKAN dalam bentuk BUKU REFERENSI
I3: dan Kepala Badan Kepegawaian Negara | V3: 1).c).Hasil penelitian atau hasil pemikiran yang DIPUBLIKASIKAN dalam bentuk JURNAL ILMIAH INTERNASIONAL
I4: Nomor : 4/VIII/PB/2014 | V4: 1).d).Hasil penelitian atau hasil pemikiran yang DIPUBLIKASIKAN dalam bentuk JURNAL ILMIAH NASIONAL TERAKREDITASI
I5: Nomor : 24 TAHUN 2014 | V5: 1).e).Hasil penelitian atau hasil pemikiran yang DIPUBLIKASIKAN dalam bentuk JURNAL ILMIAH TIDAK TERAKREDITASI
I6: Tentang Ketentuan Pelaksanaan Peraturan Menteri Pendayagunaan Aparatur Negara Dan Reformasi Birokrasi Nomor 17 Tahun 2013 Tentang Jabatan Fungsional Dosen Dan Angka Kreditnya, Sebagaimana Telah Diubah Dengan Peraturan Menteri Pendayagunaan Aparatur Negara Dan Reformasi Birokrasi Republik Indonesia Nomor 46 Tahun 2013 | V6: 1).f).Hasil penelitian atau hasil pemikiran yang DIPUBLIKASIKAN melalui SEMINAR DISAJIKAN TINGKAT INTERNASIONAL
V7: 1).g).Hasil penelitian atau hasil pemikiran yang DIPUBLIKASIKAN melalui SEMINAR DISAJIKAN TINGKAT NASIONAL
A8: SURAT PERNYATAAN | V8: 1).h).Hasil penelitian atau hasil pemikiran yang DIPUBLIKASIKAN melalui SEMINAR POSTER TINGKAT INTERNASIONAL
A9: MELAKSANAKAN PENELITIAN | V9: 1).i).Hasil penelitian atau hasil pemikiran yang DIPUBLIKASIKAN melalui SEMINAR POSTER TINGKAT NASIONAL
A10: Yang Bertanda Tangan di Bawah Ini
A11: 1 | B11: N a m a | D11: =IF('LAMPIRAN II DONE'!C11<>"",'LAMPIRAN II DONE'!C11,"")
A12: 2 | B12: N I P | D12: =IF('LAMPIRAN II DONE'!C12<>"",'LAMPIRAN II DONE'!C12,"")
A13: 3 | B13: Pangkat/Golongan Ruang | D13: =IF('LAMPIRAN II DONE'!C13<>"",'LAMPIRAN II DONE'!C13,"")
A14: 4 | B14: Jabatan Fungsional | D14: =IF('LAMPIRAN II DONE'!C14<>"",'LAMPIRAN II DONE'!C14,"")
A15: 5 | B15: Unit Kerja | D15: =IF('LAMPIRAN II DONE'!C15<>"",'LAMPIRAN II DONE'!C15,"")
A16: Menyatakan Bahwa
A17: 1 | B17: NAMA | D17: =IF('LAMPIRAN I DONE'!F15<>"",'LAMPIRAN I DONE'!F15,"") -> Dahliar Ananda | K17: Petunjuk | V17: 1).j).Hasil penelitian atau hasil pemikiran yang DIPUBLIKASIKAN dalam bentuk KORAN/MAJALAH POPULER/UMUM
A18: 2 | B18: NIP/NIDN | D18: =IF('LAMPIRAN I DONE'!F16<>"",'LAMPIRAN I DONE'!F16,"") -> 0402058203 / 09820030 | V18: 1).k).Hasil penelitan atau hasil pemikiran yang TIDAK DIPUBLIKASIKAN (tersimpan diperpustakaan PT)
A19: 3 | B19: JABATAN FUNGSIONAL | D19: =IF('LAMPIRAN I DONE'!F21<>"",'LAMPIRAN I DONE'!F21,"") -> Lektor | L19: : Kotak berwarna HIJAU untuk dipilih sesuai pilihan yang ada
A20: 4 | B20: UNIT KERJA | D20: =IF('LAMPIRAN I DONE'!F25<>"",'LAMPIRAN I DONE'!F25,"") -> S1 Rekayasa Perangkat Lunak Kampus Surabaya Fakultas Informatika di Universitas Telkom pada LLDIKTI Wilayah IV Jawa Barat dan Banten | L20: : Kotak berwarna MERAH rumus
L21: Untuk Row yang tidak diisi / dilewat mohon dihide
A22: NO | B22: URAIAN KEGIATAN | D22: TANGGAL | E22: SATUAN HASIL | F22: JUMLAH VOLUME KEGIATAN | G22: ANGKA KREDIT | H22: JUMLAH ANGKA KREDIT | I22: AK KOPERTIS | J22: KETERANGAN / BUKTI FISIK | L22: Created By : Nathaleo M. Apon.
A25: 1 | B25: 2 | D25: 3 | E25: 4 | G25: 5 | H25: 6 | I25: 7 | J25: 7
A26: III | B26: Pelaksanaan Penelitian
A27: A | B27: Menghasilkan karya ilmiah | K27: penulis | L27: kriteria karya ilmiah
A28: Hasil Penelitian Atau Hasil Pemikiran Yang Dipublikasikan Pada Jurnal Internasional
A29: 1 | B29: Nama : | C29: aaa | D29: 14 Februari 2014 | E29: Jurnal International Bereputasi | F29: =M29 -> rumus | G29: =IF(N29<>"rumus",M29&" x "&N29&" = "&M29*N29,"rumus") -> rumus | H29: =O29 -> 0 | J29: Jurnal Internasional (cantumkan SJR jika ada) Link Url | M29: =IF(K29="1 Penulis (ke-1)",100%,IF(K29="2 Penulis (ke-1)",60%,IF(K29="2 Penulis (ke-2)",40%,IF(K29="3 Penulis (ke-1)",60%,IF(K29="3 Penulis (ke-2)",20%,IF(K29="3 Penulis (ke-3)",20%,IF(K29="4 Penulis (ke-1)",60%,IF(K29="4 Penulis (ke-2)",13.3%,IF(K29="4 Penulis (ke-3)",13.3%,IF(K29="4 Penulis (ke-4)",13.3%,"rumus")))))))))) -> rumus | N29: =IF(L29<>"",VLOOKUP(L29,List!$E$2:$F$23,2,0),"rumus") -> rumus | O29: =IFERROR(M29*N29,0) -> 0 | P29: =VLOOKUP(L29,List!$E$2:$G$23,3,0) -> #N/A | Q29: =IF(RIGHT(K29,6)="(ke-1)","Penulis Utama",IF(K29="","","Pendamping"))
B30: Judul : | C30: aaa
A31: 2 | B31: Nama : | C31: aaa | F31: =M31 -> rumus | G31: =IF(N31<>"rumus",M31&" x "&N31&" = "&M31*N31,"rumus") -> rumus | H31: =O31 -> 0 | J31: - | M31: =IF(K31="1 Penulis (ke-1)",100%,IF(K31="2 Penulis (ke-1)",60%,IF(K31="2 Penulis (ke-2)",40%,IF(K31="3 Penulis (ke-1)",60%,IF(K31="3 Penulis (ke-2)",20%,IF(K31="3 Penulis (ke-3)",20%,IF(K31="4 Penulis (ke-1)",60%,IF(K31="4 Penulis (ke-2)",13.3%,IF(K31="4 Penulis (ke-3)",13.3%,IF(K31="4 Penulis (ke-4)",13.3%,"rumus")))))))))) -> rumus | N31: =IF(L31<>"",VLOOKUP(L31,List!$E$2:$F$23,2,0),"rumus") -> rumus | O31: =IFERROR(M31*N31,0) -> 0 | P31: =VLOOKUP(L31,List!$E$2:$G$23,3,0) -> #N/A | Q31: =IF(RIGHT(K31,6)="(ke-1)","Penulis Utama",IF(K31="","","Pendamping"))
B32: Judul : | C32: aaa
A33: 3 | B33: Nama : | F33: =M33 -> rumus | G33: =IF(N33<>"rumus",M33&" x "&N33&" = "&M33*N33,"rumus") -> rumus | H33: =O33 -> 0 | J33: - | M33: =IF(K33="1 Penulis (ke-1)",100%,IF(K33="2 Penulis (ke-1)",60%,IF(K33="2 Penulis (ke-2)",40%,IF(K33="3 Penulis (ke-1)",60%,IF(K33="3 Penulis (ke-2)",20%,IF(K33="3 Penulis (ke-3)",20%,IF(K33="4 Penulis (ke-1)",60%,IF(K33="4 Penulis (ke-2)",13.3%,IF(K33="4 Penulis (ke-3)",13.3%,IF(K33="4 Penulis (ke-4)",13.3%,"rumus")))))))))) -> rumus | N33: =IF(L33<>"",VLOOKUP(L33,List!$E$2:$F$23,2,0),"rumus") -> rumus | O33: =IFERROR(M33*N33,0) -> 0 | P33: =VLOOKUP(L33,List!$E$2:$G$23,3,0) -> #N/A | Q33: =IF(RIGHT(K33,6)="(ke-1)","Penulis Utama",IF(K33="","","Pendamping"))
B34: Judul :
A35: 4 | B35: Nama : | F35: =M35 -> rumus | G35: =IF(N35<>"rumus",M35&" x "&N35&" = "&M35*N35,"rumus") -> rumus | H35: =O35 -> 0 | J35: - | M35: =IF(K35="1 Penulis (ke-1)",100%,IF(K35="2 Penulis (ke-1)",60%,IF(K35="2 Penulis (ke-2)",40%,IF(K35="3 Penulis (ke-1)",60%,IF(K35="3 Penulis (ke-2)",20%,IF(K35="3 Penulis (ke-3)",20%,IF(K35="4 Penulis (ke-1)",60%,IF(K35="4 Penulis (ke-2)",13.3%,IF(K35="4 Penulis (ke-3)",13.3%,IF(K35="4 Penulis (ke-4)",13.3%,"rumus")))))))))) -> rumus | N35: =IF(L35<>"",VLOOKUP(L35,List!$E$2:$F$23,2,0),"rumus") -> rumus | O35: =IFERROR(M35*N35,0) -> 0 | P35: =VLOOKUP(L35,List!$E$2:$G$23,3,0) -> #N/A | Q35: =IF(RIGHT(K35,6)="(ke-1)","Penulis Utama",IF(K35="","","Pendamping"))
B36: Judul :
A37: 5 | B37: Nama : | F37: =M37 -> rumus | G37: =IF(N37<>"rumus",M37&" x "&N37&" = "&M37*N37,"rumus") -> rumus | H37: =O37 -> 0 | J37: - | M37: =IF(K37="1 Penulis (ke-1)",100%,IF(K37="2 Penulis (ke-1)",60%,IF(K37="2 Penulis (ke-2)",40%,IF(K37="3 Penulis (ke-1)",60%,IF(K37="3 Penulis (ke-2)",20%,IF(K37="3 Penulis (ke-3)",20%,IF(K37="4 Penulis (ke-1)",60%,IF(K37="4 Penulis (ke-2)",13.3%,IF(K37="4 Penulis (ke-3)",13.3%,IF(K37="4 Penulis (ke-4)",13.3%,"rumus")))))))))) -> rumus | N37: =IF(L37<>"",VLOOKUP(L37,List!$E$2:$F$23,2,0),"rumus") -> rumus | O37: =IFERROR(M37*N37,0) -> 0 | P37: =VLOOKUP(L37,List!$E$2:$G$23,3,0) -> #N/A | Q37: =IF(RIGHT(K37,6)="(ke-1)","Penulis Utama",IF(K37="","","Pendamping"))
B38: Judul :
A39: 6 | B39: Nama : | F39: =M39 -> rumus | G39: =IF(N39<>"rumus",M39&" x "&N39&" = "&M39*N39,"rumus") -> rumus | H39: =O39 -> 0 | J39: - | M39: =IF(K39="1 Penulis (ke-1)",100%,IF(K39="2 Penulis (ke-1)",60%,IF(K39="2 Penulis (ke-2)",40%,IF(K39="3 Penulis (ke-1)",60%,IF(K39="3 Penulis (ke-2)",20%,IF(K39="3 Penulis (ke-3)",20%,IF(K39="4 Penulis (ke-1)",60%,IF(K39="4 Penulis (ke-2)",13.3%,IF(K39="4 Penulis (ke-3)",13.3%,IF(K39="4 Penulis (ke-4)",13.3%,"rumus")))))))))) -> rumus | N39: =IF(L39<>"",VLOOKUP(L39,List!$E$2:$F$23,2,0),"rumus") -> rumus | O39: =IFERROR(M39*N39,0) -> 0 | P39: =VLOOKUP(L39,List!$E$2:$G$23,3,0) -> #N/A | Q39: =IF(RIGHT(K39,6)="(ke-1)","Penulis Utama",IF(K39="","","Pendamping"))
B40: Judul :
A41: 7 | B41: Nama : | F41: =M41 -> rumus | G41: =IF(N41<>"rumus",M41&" x "&N41&" = "&M41*N41,"rumus") -> rumus | H41: =O41 -> 0 | J41: - | M41: =IF(K41="1 Penulis (ke-1)",100%,IF(K41="2 Penulis (ke-1)",60%,IF(K41="2 Penulis (ke-2)",40%,IF(K41="3 Penulis (ke-1)",60%,IF(K41="3 Penulis (ke-2)",20%,IF(K41="3 Penulis (ke-3)",20%,IF(K41="4 Penulis (ke-1)",60%,IF(K41="4 Penulis (ke-2)",13.3%,IF(K41="4 Penulis (ke-3)",13.3%,IF(K41="4 Penulis (ke-4)",13.3%,"rumus")))))))))) -> rumus | N41: =IF(L41<>"",VLOOKUP(L41,List!$E$2:$F$23,2,0),"rumus") -> rumus | O41: =IFERROR(M41*N41,0) -> 0 | P41: =VLOOKUP(L41,List!$E$2:$G$23,3,0) -> #N/A | Q41: =IF(RIGHT(K41,6)="(ke-1)","Penulis Utama",IF(K41="","","Pendamping"))
B42: Judul :
...

Sheet List
B1: =COUNTIF(A2:A4,"<>-") -> 3
A2: =IF('LAMPIRAN I DONE'!F21="lektor kepala","GURU BESAR (IV/d)",IF('LAMPIRAN I DONE'!F21="lektor","LEKTOR KEPALA (IV/a)",IF('LAMPIRAN I DONE'!F21="asisten ahli","LEKTOR (III/c)",IF('LAMPIRAN I DONE'!F21="tenaga pengajar","ASISTEN AHLI (III/b)","-")))) -> LEKTOR KEPALA (IV/a) | B2: - | C2: S2 Teknik Elektro Fakultas Teknik Elektro | D2: S2 Teknik Elektro Fakultas Teknik Elektro di Universitas Telkom pada LLDIKTI Wilayah IV Jawa Barat dan Banten | E2: 1.a).1). DIPUBLIKASIKAN dalam bentuk BUKU REFERENSI | F2: 40 | G2: A.1.a.1 | K2: ASISTEN AHLI (III/b) | L2: 0 | M2: 0 | N2: ≥ 55% | O2: ≥ 25% | P2: ≤ 10% | Q2: ≤ 10% | R2: ='Rekapitulasi (S3)'!D33 -> 0 | S2: =W2 -> 0 | T2: ='Rekapitulasi (S3)'!D30 -> 0 | U2: ='Rekapitulasi (S3)'!D31 -> 0 | V2: ='Rekapitulasi (S3)'!D32 -> 0 | W2: ='Rekapitulasi (S3)'!E28 -> 0 | X2: ='Rekapitulasi (S3)'!E30 -> 0 | Z2: a.internasional yang sudah diimplementasikan di industri (diakui minimal 4 negara) | AA2: 60 | AB2: Komposer/penulis naskah/sutradara/perancang/pencipta/pengubah/kameramen/animator/kurator/editor audio visual
A3: =IF('LAMPIRAN I DONE'!F21="lektor kepala","GURU BESAR (IV/e)",IF('LAMPIRAN I DONE'!F21="lektor","LEKTOR KEPALA (IV/b)",IF('LAMPIRAN I DONE'!F21="asisten ahli","LEKTOR (III/d)",IF('LAMPIRAN I DONE'!F21="tenaga pengajar","-","-")))) -> LEKTOR KEPALA (IV/b) | B3: Penata Muda, ruang III/a | C3: S1 Teknik Elektro Fakultas Teknik Elektro | D3: S1 Teknik Elektro Fakultas Teknik Elektro di Universitas Telkom pada LLDIKTI Wilayah IV Jawa Barat dan Banten | E3: 1.a).2). DIPUBLIKASIKAN dalam bentuk BUKU MONOGRAF | F3: 20 | G3: A.1.a.2 | H3: Januari | I3: 1 | J3: 2001 | K3: LEKTOR (III/c) | L3: 0 | M3: 0 | N3: ≥ 45% | O3: ≥ 35% | P3: ≤ 10% | Q3: ≤ 10% | R3: ='Rekapitulasi (S3)'!D41 -> 0 | S3: ='Rekapitulasi (S3)'!D36 -> 0 | T3: ='Rekapitulasi (S3)'!D38 -> 0 | U3: ='Rekapitulasi (S3)'!D39 -> 0 | V3: ='Rekapitulasi (S3)'!D40 -> 0 | W3: ='Rekapitulasi (S3)'!E36 -> 0 | X3: ='Rekapitulasi (S3)'!E38 -> 0 | Z3: b.internasional (diakui minimal 4 negara) | AA3: 50 | AB3: penata artistik/penata musik/penata rias/penata busana/penata tari/penata lampu/penata suara/penata panggung/ilustrator/foto/konduktor
A4: =IF('LAMPIRAN I DONE'!F21="lektor kepala","-",IF('LAMPIRAN I DONE'!F21="lektor","LEKTOR KEPALA (IV/c)",IF('LAMPIRAN I DONE'!F21="asisten ahli","-",IF('LAMPIRAN I DONE'!F21="tenaga pengajar","-","-")))) -> LEKTOR KEPALA (IV/c) | B4: Penata Muda Tingkat I, ruang III/b | C4: S1 Teknik Telekomunikasi Fakultas Teknik Elektro | D4: S1 Teknik Telekomunikasi Fakultas Teknik Elektro di Universitas Telkom pada LLDIKTI Wilayah IV Jawa Barat dan Banten | E4: 1.b).1). Hasil penelitian atau hasil pemikiran dalam buku yang DIPUBLIKASIKAN dan berisi berbagai tulisan dari berbagai PENULIS INTERNASIONAL | F4: 15 | G4: A.1.a.1 | H4: Februari | I4: 2 | J4: 2002 | K4: LEKTOR (III/d) | L4: 90 | M4: 10 | N4: ≥ 45% | O4: ≥ 35% | P4: ≤ 10% | Q4: ≤ 10% | R4: ='Rekapitulasi (S3)'!D49 -> 0 | S4: ='Rekapitulasi (S3)'!D44 -> 0 | T4: ='Rekapitulasi (S3)'!D46 -> 0 | U4: ='Rekapitulasi (S3)'!D47 -> 0 | V4: ='Rekapitulasi (S3)'!D48 -> 0 | W4: ='Rekapitulasi (S3)'!E44 -> 0 | X4: ='Rekapitulasi (S3)'!E46 -> 0 | Z4: c.nasional (sudah diimplementasikan di industri) | AA4: 40 | AB4: pemusik/pengrawit/penari/dalang/pemeran/pengarah acara televisi/pelaksana perancangan/pendisplay pameran/pembuat foto dokumentasi/pewarta foto/pembawa acara/reporter/redaktur pelaksana
B5: Penata, ruang III/c | C5: S1 Sistem Komputer Fakultas Teknik Elektro | D5: S1 Sistem Komputer Fakultas Teknik Elektro di Universitas Telkom pada LLDIKTI Wilayah IV Jawa Barat dan Banten | E5: 1.b).2). Hasil penelitian atau hasil pemikiran dalam buku yang DIPUBLIKASIKAN dan berisi berbagai tulisan dari berbagai PENULIS NASIONAL | F5: 10 | G5: A.1.a.1 | H5: Maret | I5: 3 | J5: 2003 | K5: LEKTOR KEPALA (IV/a) | L5: 180 | M5: 20 | N5: ≥ 40% | O5: ≥ 40% | P5: ≤ 10% | Q5: ≤ 10% | R5: ='Rekapitulasi (S3)'!D57 -> 0 | S5: ='Rekapitulasi (S3)'!D52 -> 0 | T5: ='Rekapitulasi (S3)'!D54 -> 0 | U5: ='Rekapitulasi (S3)'!D55 -> 0 | V5: ='Rekapitulasi (S3)'!D56 -> 0 | W5: ='Rekapitulasi (S3)'!E52 -> 0 | X5: ='Rekapitulasi (S3)'!E54 -> 0 | Z5: d.nasional | AA5: 30 | AB5: penulis naskah drama/novel
B6: Penata Tingkat I, ruang III/d | C6: S1 Teknik Fisika Fakultas Teknik Elektro | D6: S1 Teknik Fisika Fakultas Teknik Elektro di Universitas Telkom pada LLDIKTI Wilayah IV Jawa Barat dan Banten | E6: 1.c).1). DIPUBLIKASIKAN dalam bentuk JURNAL INTERNASIONAL BEREPUTASI & BERDAMPAK | F6: 40 | G6: A.1.b.1 | H6: April | I6: 4 | J6: 2004 | K6: LEKTOR KEPALA (IV/b) | L6: 315 | M6: 35 | N6: ≥ 40% | O6: ≥ 40% | P6: ≤ 10% | Q6: ≤ 10% | R6: ='Rekapitulasi (S3)'!D65 -> 0 | S6: ='Rekapitulasi (S3)'!D60 -> 0 | T6: ='Rekapitulasi (S3)'!D62 -> 0 | U6: ='Rekapitulasi (S3)'!D63 -> 0 | V6: ='Rekapitulasi (S3)'!D64 -> 0 | W6: ='Rekapitulasi (S3)'!E60 -> 0 | X6: ='Rekapitulasi (S3)'!E62 -> 0 | Z6: e.nasional dalam bentuk paten sederhana | AA6: 20 | AB6: penulis buku kumpulan cerpen / komikus
B7: Pembina, ruang IV/a | C7: S1 Teknik Biomedik Fakultas Teknik Elektro | D7: S1 Teknik Biomedik Fakultas Teknik Elektro di Universitas Telkom pada LLDIKTI Wilayah IV Jawa Barat dan Banten | E7: 1.c).2). DIPUBLIKASIKAN dalam bentuk JURNAL INTERNASIONAL TERINDEK pada BASIS DATA INTERNASIONAL BEREPUTASI | F7: 30 | G7: A.1.b.1 | H7: Mei | I7: 5 | J7: 2005 | K7: LEKTOR KEPALA (IV/c) | L7: 450 | M7: 50 | N7: ≥ 40% | O7: ≥ 40% | P7: ≤ 10% | Q7: ≤ 10% | R7: ='Rekapitulasi (S3)'!D73 -> 0 | S7: ='Rekapitulasi (S3)'!D68 -> 0 | T7: ='Rekapitulasi (S3)'!D70 -> 0 | U7: ='Rekapitulasi (S3)'!D71 -> 0 | V7: ='Rekapitulasi (S3)'!D72 -> 0 | W7: ='Rekapitulasi (S3)'!E68 -> 0 | X7: ='Rekapitulasi (S3)'!E70 -> 0 | Z7: f.karya ciptaan, desain industri, indikasi geografis yang memiliki sertifikat dari Dirjen Kekayaan Intelektual kemenkunham | AA7: 15 | AB7: penulis buku kumpulan puisi
B8: Pembina Tingkat I, ruang IV/b | C8: S2 Teknik Industri Fakultas Rekayasa Industri | D8: S2 Teknik Industri Fakultas Rekayasa Industri di Universitas Telkom pada LLDIKTI Wilayah IV Jawa Barat dan Banten | E8: 1.c).3). DIPUBLIKASIKAN dalam bentuk JURNAL INTERNASIONAL TERINDEK pada BASIS DATA INTERNASIONAL di Luar Kategori 2 | F8: 20 | G8: A.1.b.1 | H8: Juni | I8: 6 | J8: 2006 | K8: GURU BESAR (IV/d) | L8: 585 | M8: 65 | N8: ≥ 35% | O8: ≥ 45% | P8: ≤ 10% | Q8: ≤ 10% | R8: ='Rekapitulasi (S3)'!D81 -> 0 | S8: ='Rekapitulasi (S3)'!D76 -> 0 | T8: ='Rekapitulasi (S3)'!D78 -> 0 | U8: ='Rekapitulasi (S3)'!D79 -> 0 | V8: ='Rekapitulasi (S3)'!D80 -> 0 | W8: ='Rekapitulasi (S3)'!E76 -> 0 | X8: ='Rekapitulasi (S3)'!E78 -> 0
B9: Pembina Utama Muda, ruang IV/c | C9: S1 Teknik Industri Fakultas Rekayasa Industri | D9: S1 Teknik Industri Fakultas Rekayasa Industri di Universitas Telkom pada LLDIKTI Wilayah IV Jawa Barat dan Banten | E9: 1.c).4). DIPUBLIKASIKAN dalam bentuk JURNAL NASIONAL TERAKREDITASI DIKTI DAN ATAU SINTA 1 & SINTA 2 | F9: 25 | G9: A.1.b.2 | H9: Juli | I9: 7 | J9: 2007 | K9: GURU BESAR (IV/e) | L9: 765 | M9: 85 | N9: ≥ 35% | O9: ≥ 45% | P9: ≤ 10% | Q9: ≤ 10% | R9: ='Rekapitulasi (S3)'!D89 -> 0 | S9: ='Rekapitulasi (S3)'!D84 -> 0 | T9: ='Rekapitulasi (S3)'!D86 -> 0 | U9: ='Rekapitulasi (S3)'!D87 -> 0 | V9: ='Rekapitulasi (S3)'!D88 -> 0 | W9: ='Rekapitulasi (S3)'!E84 -> 0 | X9: ='Rekapitulasi (S3)'!E86 -> 0
B10: Pembina Utama Madya, ruang IV/d | C10: S1 Sistem Informasi Fakultas Rekayasa Industri | D10: S1 Sistem Informasi Fakultas Rekayasa Industri di Universitas Telkom pada LLDIKTI Wilayah IV Jawa Barat dan Banten | E10: 1.c).5).a). DIPUBLIKASIKAN dalam bentuk JURNAL NASIONAL BERBAHASA INDONESIA terindex pada DOAJ DAN ATAU SINTA 3 & SINTA 4 | F10: 15 | G10: A.1.b.2 | H10: Agustus | I10: 8 | J10: 2008
B11: Pembina Utama, ruang IV/e | C11: S1 Teknik Logistik Fakultas Rekayasa Industri | D11: S1 Teknik Logistik Fakultas Rekayasa Industri di Universitas Telkom pada LLDIKTI Wilayah IV Jawa Barat dan Banten | E11: 1.c).5).b). DIPUBLIKASIKAN dalam bentuk JURNAL NASIONAL BERBAHASA INGGRIS atau BAHASA RESMI (PBB) terindek pada DOAJ DAN ATAU SINTA 3 & SINTA 4 | F11: 20 | G11: A.1.b.2 | H11: September | I11: 9 | J11: 2009
C12: S2 Teknik Informatika Fakultas Informatika | D12: S2 Teknik Informatika Fakultas Informatika di Universitas Telkom pada LLDIKTI Wilayah IV Jawa Barat dan Banten | E12: 1.c).6). DIPUBLIKASIKAN dalam bentuk JURNAL NASIONAL BERBAHASA INDONESIA (TIDAK MASUK SINTA) | F12: 10 | G12: A.1.b.3 | H12: Oktober | I12: 10 | J12: 2010
C13: S1 Teknik Informatika Fakultas Informatika | D13: S1 Teknik Informatika Fakultas Informatika di Universitas Telkom pada LLDIKTI Wilayah IV Jawa Barat dan Banten | E13: 1.c).7). DIPUBLIKASIKAN dalam bentuk JURNAL ILMIAH yang ditulis dalam BAHASA RESMI namum tidak memenuhi syarat-syarat sebagai JURNAL ILMIAH INTERNASIONAL | F13: 10 | G13: A.1.b.3 | H13: November | I13: 11 | J13: 2011
C14: S1 Rekayasa Perangkat Lunak Fakultas Informatika | D14: S1 Rekayasa Perangkat Lunak Fakultas Informatika di Universitas Telkom pada LLDIKTI Wilayah IV Jawa Barat dan Banten | E14: 2.a).1). DIDESIMINASIKAN DIPRESENTASIKAN secara ORAL dan dimuat dalam PROSIDING yang DIPUBLIKASISKAN (ber ISSN/ISBN) INTERNASIONAL SCOPUS/SJR | F14: 30 | G14: A.1.c.1.a | H14: Desember | I14: 12 | J14: 2012
C15: S1 Teknologi Informasi Fakultas Informatika | D15: S1 Teknologi Informasi Fakultas Informatika di Universitas Telkom pada LLDIKTI Wilayah IV Jawa Barat dan Banten | E15: 2.a).2). DIDESIMINASIKAN DIPRESENTASIKAN secara ORAL dan dimuat dalam PROSIDING yang DIPUBLIKASISKAN (ber ISSN/ISBN) INTERNASIONAL SCOPUS/IEEE EXPLORE/SPIE | F15: 25 | J15: 2013
C16: S1 Data Science Fakultas Informatika | D16: S1 Data Science Fakultas Informatika di Universitas Telkom pada LLDIKTI Wilayah IV Jawa Barat dan Banten | E16: 2.a).3). DIDESIMINASIKAN DIPRESENTASIKAN secara ORAL dan dimuat dalam PROSIDING yang DIPUBLIKASISKAN (ber ISSN/ISBN) INTERNASIONAL TIDAK TERINDEKS | F16: 15 | J16: 2014
C17: S2 Manajemen Fakultas Ekonomi dan Bisnis | D17: S2 Manajemen Fakultas Ekonomi dan Bisnis di Universitas Telkom pada LLDIKTI Wilayah IV Jawa Barat dan Banten | E17: 2.a).4). DIDESIMINASIKAN DIPRESENTASIKAN secara ORAL dan dimuat dalam PROSIDING yang DIPUBLIKASISKAN (ber ISSN/ISBN) NASIONAL TIDAK TERINDEKS | F17: 10 | G17: A.1.c.1.b | J17: 2015
C18: S1 Manajemen Fakultas Ekonomi dan Bisnis | D18: S1 Manajemen Fakultas Ekonomi dan Bisnis di Universitas Telkom pada LLDIKTI Wilayah IV Jawa Barat dan Banten | E18: 2.b).1). DISAJIKAN dalam bentuk POSTER dan dimuat dalam PROSIDING yang DIPUBLIKASIKAN INTERNASIONAL | F18: 10 | G18: A.1.c.2.a | J18: 2016
C19: S1 Akuntansi Fakultas Ekonomi dan Bisnis | D19: S1 Akuntansi Fakultas Ekonomi dan Bisnis di Universitas Telkom pada LLDIKTI Wilayah IV Jawa Barat dan Banten | E19: 2.b).2). DISAJIKAN dalam bentuk POSTER dan dimuat dalam PROSIDING yang DIPUBLIKASIKAN NASIONAL | F19: 5 | G19: A.1.c.2.b | J19: 2017
C20: S1 Administrasi Bisnis Fakultas Komunikasi dan Bisnis | D20: S1 Administrasi Bisnis Fakultas Komunikasi dan Bisnis di Universitas Telkom pada LLDIKTI Wilayah IV Jawa Barat dan Banten | E20: 2.c).1). DISAJIKAN dalam SEMINAR/SIMPOSIUM/LOKAKARYA, tetapi TIDAK DIMUAT dalam PROSIDING yang DIPUBLIKASIKAN INTERNASIONAL | F20: 5 | G20: A.1.c.1.a | J20: 2018
C21: S1 Ilmu Komunikasi Fakultas Komunikasi dan Bisnis | D21: S1 Ilmu Komunikasi Fakultas Komunikasi dan Bisnis di Universitas Telkom pada LLDIKTI Wilayah IV Jawa Barat dan Banten | E21: 2.c).2). DISAJIKAN dalam SEMINAR/SIMPOSIUM/LOKAKARYA, tetapi TIDAK DIMUAT dalam PROSIDING yang DIPUBLIKASIKAN NASIONAL | F21: 3 | G21: A.1.c.1.b | J21: 2019
C22: S1 Digital Broadcasting Fakultas Komunikasi dan Bisnis | D22: S1 Digital Broadcasting Fakultas Komunikasi dan Bisnis di Universitas Telkom pada LLDIKTI Wilayah IV Jawa Barat dan Banten | E22: 2.d).1). TIDAK DISAJIKAN dalam SEMINAR/SIMPOSIUM/LOKAKARYA, tetapi dimuat dalam PROSIDING INTERNASIONAL | F22: 10 | G22: A.1.c.1.a | J22: 2020
C23: S1 Seni Rupa Murni Fakultas Industri Kreatif | D23: S1 Seni Rupa Murni Fakultas Industri Kreatif di Universitas Telkom pada LLDIKTI Wilayah IV Jawa Barat dan Banten | E23: 2.d).2). TIDAK DISAJIKAN dalam SEMINAR/SIMPOSIUM/LOKAKARYA, tetapi dimuat dalam PROSIDING NASIONAL | F23: 5 | G23: A.1.c.1.b | J23: 2021
C24: S1 Kriya Tekstil Dan Mode Fakultas Industri Kreatif | D24: S1 Kriya Tekstil Dan Mode Fakultas Industri Kreatif di Universitas Telkom pada LLDIKTI Wilayah IV Jawa Barat dan Banten | E24: 2.e). DISAJIKAN dalam KORAN/MAJALAH POPULER/UMUM | F24: 1 | G24: A.1.d | J24: 2022
C25: S1 Desain Interior Fakultas Industri Kreatif | D25: S1 Desain Interior Fakultas Industri Kreatif di Universitas Telkom pada LLDIKTI Wilayah IV Jawa Barat dan Banten | E25: 3. Hasil penelitian atau hasil pemikiran atau KERJASAMA INDUSTRI yang TIDAK DIPUBLIKASIKAN (tersimpan dalam perpustakaan) | F25: 2 | G25: A.2 | J25: 2023
C26: S1 Desain Produk Fakultas Industri Kreatif | D26: S1 Desain Produk Fakultas Industri Kreatif di Universitas Telkom pada LLDIKTI Wilayah IV Jawa Barat dan Banten | J26: 2024
C27: S1 Desain Komunikasi Visual Fakultas Industri Kreatif | D27: S1 Desain Komunikasi Visual Fakultas Industri Kreatif di Universitas Telkom pada LLDIKTI Wilayah IV Jawa Barat dan Banten | J27: 2025
C28: D4 Sistem Multimedia Fakultas Ilmu Terapan | D28: D4 Sistem Multimedia Fakultas Ilmu Terapan di Universitas Telkom pada LLDIKTI Wilayah IV Jawa Barat dan Banten | J28: 2026
C29: D3 Teknik Telekomunikasi Fakultas Ilmu Terapan | D29: D3 Teknik Telekomunikasi Fakultas Ilmu Terapan di Universitas Telkom pada LLDIKTI Wilayah IV Jawa Barat dan Banten | J29: 2027
C30: D3 Teknik Informatika Fakultas Ilmu Terapan | D30: D3 Teknik Informatika Fakultas Ilmu Terapan di Universitas Telkom pada LLDIKTI Wilayah IV Jawa Barat dan Banten | J30: 2028
C31: D3 Teknik Komputer Fakultas Ilmu Terapan | D31: D3 Teknik Komputer Fakultas Ilmu Terapan di Universitas Telkom pada LLDIKTI Wilayah IV Jawa Barat dan Banten | J31: 2029
C32: D3 Sistem Informasi Fakultas Ilmu Terapan | D32: D3 Sistem Informasi Fakultas Ilmu Terapan di Universitas Telkom pada LLDIKTI Wilayah IV Jawa Barat dan Banten | J32: 2030
C33: D3 Sistem Informasi Akuntansi Fakultas Ilmu Terapan | D33: D3 Sistem Informasi Akuntansi Fakultas Ilmu Terapan di Universitas Telkom pada LLDIKTI Wilayah IV Jawa Barat dan Banten
C34: D3 Manajemen Pemasaran Fakultas Ilmu Terapan | D34: D3 Manajemen Pemasaran Fakultas Ilmu Terapan di Universitas Telkom pada LLDIKTI Wilayah IV Jawa Barat dan Banten
C35: D3 Perhotelan Fakultas Ilmu Terapan | D35: D3 Perhotelan Fakultas Ilmu Terapan di Universitas Telkom pada Kopertis LLDIKTI Wilayah IV Jawa Barat dan Banten
C36: S1 Rekayasa Perangkat Lunak Kampus Surabaya Fakultas Informatika | D36: S1 Rekayasa Perangkat Lunak Kampus Surabaya Fakultas Informatika di Universitas Telkom pada LLDIKTI Wilayah IV Jawa Barat dan Banten
C37: S1 Informatika Kampus Surabaya Fakultas Informatika | D37: S1 Informatika Kampus Surabaya Fakultas Informatika di Universitas Telkom pada LLDIKTI Wilayah IV Jawa Barat dan Banten
C38: S1 Teknologi Informasi Kampus Surabaya Fakultas Informatika | D38: S1 Teknologi Informasi Kampus Surabaya Fakultas Informatika di Universitas Telkom pada LLDIKTI Wilayah IV Jawa Barat dan Banten
C39: S1 Sains Data Kampus Surabaya Fakultas Informatika | D39: S1 Sains Data Kampus Surabaya Fakultas Informatika di Universitas Telkom pada LLDIKTI Wilayah IV Jawa Barat dan Banten
C40: S1 Teknik Industri Kampus Surabaya Fakultas Rekayasa Industri | D40: S1 Teknik Industri Kampus Surabaya Fakultas Rekayasa Industri di Universitas Telkom pada LLDIKTI Wilayah IV Jawa Barat dan Banten
...

Sheet LAMPIRAN IV DONE
F1: Lampiran VII Keputusan Bersama Menteri | S1: a.1).Terjadwal/terprogram Dalam satu semester atau lebih Tingkat Internasional tiap program
F2: Pendidikan dan Kebudayaan | S2: a.2).Terjadwal/terprogram Dalam satu semester atau lebih Tingkat Nasional tiap program
F3: dan Kepala Badan Kepegawaian Negara | S3: a.3).Terjadwal/terprogram Dalam satu semester atau lebih Tingkat Lokal tiap program
F4: Nomor : 4/VIII/PB/2014 | S4: a.4).Terjadwal/terprogram Kurang dari satu semester dan minimal satu bulan Tingkat Internasional tiap program
F5: Nomor : 24 TAHUN 2014 | S5: a.5).Terjadwal/terprogram Kurang dari satu semester dan minimal satu bulan Tingkat Nasional tiap program
F6: Tentang Ketentuan Pelaksanaan Peraturan Menteri Pendayagunaan Aparatur Negara Dan Reformasi Birokrasi Nomor 17 Tahun 2013 Tentang Jabatan Fungsional Dosen Dan Angka Kreditnya, Sebagaimana Telah Diubah Dengan Peraturan Menteri Pendayagunaan Aparatur Negara Dan Reformasi Birokrasi Republik Indonesia Nomor 46 Tahun 2013 | S6: a.6).Terjadwal/terprogram Kurang dari satu semester dan minimal satu bulan Tingkat Lokal tiap program
A7: SURAT PERNYATAAN | S7: b.Insidental, tiap kegiatan program
A8: MELAKSANAKAN KEGIATAN PENGABDIAN PADA MASYARAKAT
A9: Yang bertanda tangan di bawah ini: | I9: Petunjuk
A10: 1 | B10: Nama | C10: =IF('LAMPIRAN II DONE'!C11<>"",'LAMPIRAN II DONE'!C11,"")
A11: 2 | B11: NIP/NIDN | C11: =IF('LAMPIRAN II DONE'!C12<>"",'LAMPIRAN II DONE'!C12,"") | J11: : Kotak berwarna HIJAU untuk dipilih sesuai pilihan yang ada
A12: 3 | B12: Pangkat/Golongan Ruang | C12: =IF('LAMPIRAN II DONE'!C13<>"",'LAMPIRAN II DONE'!C13,"") | J12: : Kotak berwarna MERAH rumus
A13: 4 | B13: Jabatan Fungsional | C13: =IF('LAMPIRAN II DONE'!C14<>"",'LAMPIRAN II DONE'!C14,"") | J13: Untuk Row yang tidak diisi / dilewat mohon dihide
A14: 5 | B14: Unit Kerja | C14: =IF('LAMPIRAN II DONE'!C15<>"",'LAMPIRAN II DONE'!C15,"") | J14: Created By : Nathaleo M. Apon.
A15: Menyatakan Bahwa
A16: 1 | B16: Nama | C16: =IF('LAMPIRAN I DONE'!F15<>"",'LAMPIRAN I DONE'!F15,"") -> Dahliar Ananda
A17: 2 | B17: NIP/NIDN | C17: =IF('LAMPIRAN I DONE'!F16<>"",'LAMPIRAN I DONE'!F16,"") -> 0402058203 / 09820030
A18: 3 | B18: Pangkat/Golongan Ruang | C18: =IF('LAMPIRAN II DONE'!C19<>"",'LAMPIRAN II DONE'!C19,"") -> -
A19: 4 | B19: Jabatan Fungsional | C19: =IF('LAMPIRAN I DONE'!F21<>"",'LAMPIRAN I DONE'!F21,"") -> Lektor
A20: 5 | B20: Unit Kerja | C20: =IF('LAMPIRAN I DONE'!F25<>"",'LAMPIRAN I DONE'!F25,"") -> S1 Rekayasa Perangkat Lunak Kampus Surabaya Fakultas Informatika di Universitas Telkom pada LLDIKTI Wilayah IV Jawa Barat dan Banten
A21: Telah Melakukan Kegiatan Pengabdian Pada Masyarakat sebagai berikut:
A22: NO | B22: URAIAN KEGIATAN | C22: TANGGAL | D22: SATUAN HASIL | E22: JUMLAH VOLUME KEGIATAN | F22: ANGKA KREDIT | G22: JUMLAH ANGKA KREDIT | H22: KETERANGAN / BUKTI FISIK
A23: 1 | B23: 2 | C23: 3 | D23: 4 | E23: 5 | F23: 6 | G23: 7 | H23: 8
A24: IV | B24: Pelaksana Pengabdian kepada Masyarakat
A25: A | B25: Menduduki jabatan pimpinan
A26: 1 | B26: KETUA PEMBINA USAHA TANI( CONTOH ) | C26: JAN- DES 2014 | D26: SK | E26: =IF(I26<>"",1,"") | F26: =IF(I26<>"",J26,"") | G26: =IF(J26<>"rumus","1 x "&J26&" = "&J26,"rumus") -> rumus | H26: SK. KEP 0976/00/DGA-04/2017 | J26: =IF(I26="Menduduki jabatan pimpinan persemester",5.5,"rumus") -> rumus
A27: 2 | B27: posisi | C27: - | E27: =IF(I27<>"",1,"") | F27: =IF(I27<>"",J27,"") | G27: =IF(J27<>"rumus","1 x "&J27&" = "&J27,"rumus") -> rumus | H27: - | J27: =IF(I27="Menduduki jabatan pimpinan persemester",5.5,"rumus") -> rumus
A28: 3 | B28: posisi | C28: - | E28: =IF(I28<>"",1,"") | F28: =IF(I28<>"",J28,"") | G28: =IF(J28<>"rumus","1 x "&J28&" = "&J28,"rumus") -> rumus | H28: - | J28: =IF(I28="Menduduki jabatan pimpinan persemester",5.5,"rumus") -> rumus
A29: 4 | B29: posisi | C29: - | E29: =IF(I29<>"",1,"") | F29: =IF(I29<>"",J29,"") | G29: =IF(J29<>"rumus","1 x "&J29&" = "&J29,"rumus") -> rumus | H29: - | J29: =IF(I29="Menduduki jabatan pimpinan persemester",5.5,"rumus") -> rumus
A30: 5 | B30: posisi | C30: - | E30: =IF(I30<>"",1,"") | F30: =IF(I30<>"",J30,"") | G30: =IF(J30<>"rumus","1 x "&J30&" = "&J30,"rumus") -> rumus | H30: - | J30: =IF(I30="Menduduki jabatan pimpinan persemester",5.5,"rumus") -> rumus
A31: 6 | B31: posisi | C31: - | E31: =IF(I31<>"",1,"") | F31: =IF(I31<>"",J31,"") | G31: =IF(J31<>"rumus","1 x "&J31&" = "&J31,"rumus") -> rumus | H31: - | J31: =IF(I31="Menduduki jabatan pimpinan persemester",5.5,"rumus") -> rumus
A32: 7 | B32: posisi | C32: - | E32: =IF(I32<>"",1,"") | F32: =IF(I32<>"",J32,"") | G32: =IF(J32<>"rumus","1 x "&J32&" = "&J32,"rumus") -> rumus | H32: - | J32: =IF(I32="Menduduki jabatan pimpinan persemester",5.5,"rumus") -> rumus
A33: 8 | B33: posisi | C33: - | E33: =IF(I33<>"",1,"") | F33: =IF(I33<>"",J33,"") | G33: =IF(J33<>"rumus","1 x "&J33&" = "&J33,"rumus") -> rumus | H33: - | J33: =IF(I33="Menduduki jabatan pimpinan persemester",5.5,"rumus") -> rumus
A34: 9 | B34: posisi | C34: - | E34: =IF(I34<>"",1,"") | F34: =IF(I34<>"",J34,"") | G34: =IF(J34<>"rumus","1 x "&J34&" = "&J34,"rumus") -> rumus | H34: - | J34: =IF(I34="Menduduki jabatan pimpinan persemester",5.5,"rumus") -> rumus
A35: 10 | B35: posisi | C35: - | E35: =IF(I35<>"",1,"") | F35: =IF(I35<>"",J35,"") | G35: =IF(J35<>"rumus","1 x "&J35&" = "&J35,"rumus") -> rumus | H35: - | J35: =IF(I35="Menduduki jabatan pimpinan persemester",5.5,"rumus") -> rumus
B36: Jumlah | G36: =SUM(J26:J35) -> 0
A37: B | B37: Melaksanakan pengembangan hasil pendidikan & penelitian
A38: 1 | B38: Pelatihan Market Place Untuk Kebutuhan Otomotif SMK 4 LPPM | C38: JAN-JUN 2017 | D38: SK Rektor Universitas Telkom No. KR-610/ABDI3/PPM/2017 | E38: =IF(I38<>"",1,"") -> 1 | F38: =IF(I38<>"",J38,"") -> 3 | G38: =IF(J38<>"rumus","1 x "&J38&" = "&J38,"rumus") -> 1 x 3 = 3 | H38: - | I38: Melaksanakan pengembangan perprogram | J38: =IF(I38="Melaksanakan pengembangan perprogram",3,"rumus") -> 3
A39: 2 | B39: Pelatihan Desain Grafis Untuk Meningkatkan Kreativitas PDIP Kabupaten Bandung | C39: JUL-DES 2017 | D39: SK Warek IV No. KWR4-067/ABDI3/PPM/2017 | E39: =IF(I39<>"",1,"") -> 1 | F39: =IF(I39<>"",J39,"") -> 3 | G39: =IF(J39<>"rumus","1 x "&J39&" = "&J39,"rumus") -> 1 x 3 = 3 | I39: Melaksanakan pengembangan perprogram | J39: =IF(I39="Melaksanakan pengembangan perprogram",3,"rumus") -> 3
A40: 3 | B40: Pelatihan Desain Grafis untuk Meningkatkan Kreativitas Pengelola Dokumentasi Kabupaten Bandung | C40: JAN-JUN 2018 | D40: SK Warek IV No. KWR4-068/ABDI3/PPM/2018 | E40: =IF(I40<>"",1,"") -> 1 | F40: =IF(I40<>"",J40,"") -> 3 | G40: =IF(J40<>"rumus","1 x "&J40&" = "&J40,"rumus") -> 1 x 3 = 3 | I40: Melaksanakan pengembangan perprogram | J40: =IF(I40="Melaksanakan pengembangan perprogram",3,"rumus") -> 3
...

Sheet LAMPIRAN V DONE
F1: Lampiran VIII Keputusan Bersama Menteri | U1: 1) TINGKAT INTERNASIONAL Sebagai PENGURUS | V1: a.1). Tingkat Internasional/Nasional/Regional sebagai Ketua, tiap kegiatan
F2: Pendidikan dan Kebudayaan | U2: 2) TINGKAT INTERNASIONAL Sebagai ANGGOTA ATAS PERMINTAAN | V2: a.2). Tingkat Internasional/Nasional/Regional sebagai Anggota/peserta, tiap kegiatan
F3: dan Kepala Badan Kepegawaian Negara | U3: 3) TINGKAT INTERNASIONAL Sebagai ANGGOTA | V3: b.1). Di Lingkungan Perguruan Tinggi sebagai Ketua, tiap kegiatan
F4: Nomor : 4/VIII/PB/2014 | U4: 4) TINGKAT NASIONAL Sebagai PENGURUS | V4: b.2). Di Lingkungan Perguruan Tinggi sebagai Anggota/peserta, tiap kegiatan
F5: Nomor : 24 TAHUN 2014 | U5: 5) TINGKAT NASIONAL Sebagai ANGGOTA ATAS PERMINTAAN
F6: Tentang Ketentuan Pelaksanaan Peraturan Menteri Pendayagunaan Aparatur Negara Dan Reformasi Birokrasi Nomor 17 Tahun 2013 Tentang Jabatan Fungsional Dosen Dan Angka Kreditnya, Sebagaimana Telah Diubah Dengan Peraturan Menteri Pendayagunaan Aparatur Negara Dan Reformasi Birokrasi Republik Indonesia Nomor 46 Tahun 2013 | U6: 6) TINGKAT NASIONAL Sebagai ANGGOTA
A7: SURAT PERNYATAAN
A8: MELAKSANAKAN KEGIATAN PENUNJANG TUGAS DOSEN
A9: Yang bertanda tangan di bawah ini:
A10: 1 | B10: Nama | C10: =IF('LAMPIRAN II DONE'!C11<>"",'LAMPIRAN II DONE'!C11,"")
A11: 2 | B11: NIP/NIDN | C11: =IF('LAMPIRAN II DONE'!C12<>"",'LAMPIRAN II DONE'!C12,"")
A12: 3 | B12: Pangkat/Golongan Ruang | C12: =IF('LAMPIRAN II DONE'!C13<>"",'LAMPIRAN II DONE'!C13,"")
A13: 4 | B13: Jabatan Fungsional | C13: =IF('LAMPIRAN II DONE'!C14<>"",'LAMPIRAN II DONE'!C14,"")
A14: 5 | B14: Unit Kerja | C14: =IF('LAMPIRAN II DONE'!C15<>"",'LAMPIRAN II DONE'!C15,"")
A15: Menyatakan Bahwa
A16: 1 | B16: Nama | C16: =IF('LAMPIRAN I DONE'!F15<>"",'LAMPIRAN I DONE'!F15,"") -> Dahliar Ananda
A17: 2 | B17: NIP/NIDN | C17: =IF('LAMPIRAN I DONE'!F16<>"",'LAMPIRAN I DONE'!F16,"") -> 0402058203 / 09820030 | I17: Petunjuk
A18: 3 | B18: Pangkat/Golongan Ruang | C18: =IF('LAMPIRAN II DONE'!C19<>"",'LAMPIRAN II DONE'!C19,"") -> -
A19: 4 | B19: Jabatan Fungsional | C19: =IF('LAMPIRAN I DONE'!F21<>"",'LAMPIRAN I DONE'!F21,"") -> Lektor | J19: : Kotak berwarna HIJAU untuk dipilih sesuai pilihan yang ada
A20: 5 | B20: Unit Kerja | C20: =IF('LAMPIRAN I DONE'!F25<>"",'LAMPIRAN I DONE'!F25,"") -> S1 Rekayasa Perangkat Lunak Kampus Surabaya Fakultas Informatika di Universitas Telkom pada LLDIKTI Wilayah IV Jawa Barat dan Banten | J20: : Kotak berwarna MERAH rumus
A21: Telah Melakukan Kegiatan Penunjang Tridharma Perguruan Tinggi sebagai berikut: | J21: Untuk Row yang tidak diisi / dilewat mohon dihide
A22: NO | B22: URAIAN KEGIATAN | C22: TANGGAL | D22: SATUAN HASIL | E22: JUMLAH VOLUME KEGIATAN | F22: ANGKA KREDIT | G22: JUMLAH ANGKA KREDIT | H22: KETERANGAN / BUKTI FISIK | J22: Created By : Nathaleo M. Apon.
A23: 1 | B23: 2 | C23: 3 | D23: 4 | E23: 5 | F23: 6 | G23: 7 | H23: 8
A24: V | B24: Penunjang Kegiatan Akademik Dosen
A25: A | B25: Menjadi anggota dalam suatu Panitia/Badan pada Perguruan Tinggi
A26: 1 | B26: Anggota tim penyusun borang akreditasi Prodi D3 RPLA 2020 | C26: 44044 | D26: SK Dekan FIT NOMOR : KD. 122/SP12/IT-DEK/2020 | E26: =IF(I26<>"",1,"") -> 1 | F26: =IF(I26<>"",J26,"") -> 2 | G26: =IF(J26<>"rumus","1 x "&J26&" = "&J26,"rumus") -> 1 x 2 = 2 | H26: KR. 2116/SDM.2/REK/2014 | I26: b.Sebagai Anggota pertahun | J26: =IF(I26<>"",IF(I26="a.Sebagai Ketua/wakil ketua pertahun",3,IF(I26="b.Sebagai Anggota pertahun",2,"")),"rumus") -> 2
A27: 2 | B27: Anggota tim penyusun Kurikulum Prodi Manajemen Informatika 2015 | C27: 42309 | D27: SK Dekan FIT NOMOR : KD. 078 /AKD4/IT-DEK/2015 | E27: =IF(I27<>"",1,"") -> 1 | F27: =IF(I27<>"",J27,"") -> 2 | G27: =IF(J27<>"rumus","1 x "&J27&" = "&J27,"rumus") -> 1 x 2 = 2 | H27: - | I27: b.Sebagai Anggota pertahun | J27: =IF(I27<>"",IF(I27="a.Sebagai Ketua/wakil ketua pertahun",3,IF(I27="b.Sebagai Anggota pertahun",2,"")),"rumus") -> 2
A28: 3 | B28: kegiatan | C28: - | E28: =IF(I28<>"",1,"") | F28: =IF(I28<>"",J28,"") | G28: =IF(J28<>"rumus","1 x "&J28&" = "&J28,"rumus") -> rumus | H28: - | J28: =IF(I28<>"",IF(I28="a.Sebagai Ketua/wakil ketua pertahun",3,IF(I28="b.Sebagai Anggota pertahun",2,"")),"rumus") -> rumus
A29: 4 | B29: kegiatan | C29: - | E29: =IF(I29<>"",1,"") | F29: =IF(I29<>"",J29,"") | G29: =IF(J29<>"rumus","1 x "&J29&" = "&J29,"rumus") -> rumus | H29: - | J29: =IF(I29<>"",IF(I29="a.Sebagai Ketua/wakil ketua pertahun",3,IF(I29="b.Sebagai Anggota pertahun",2,"")),"rumus") -> rumus
A30: 5 | B30: kegiatan | C30: - | E30: =IF(I30<>"",1,"") | F30: =IF(I30<>"",J30,"") | G30: =IF(J30<>"rumus","1 x "&J30&" = "&J30,"rumus") -> rumus | H30: - | J30: =IF(I30<>"",IF(I30="a.Sebagai Ketua/wakil ketua pertahun",3,IF(I30="b.Sebagai Anggota pertahun",2,"")),"rumus") -> rumus
A31: 6 | B31: kegiatan | C31: - | E31: =IF(I31<>"",1,"") | F31: =IF(I31<>"",J31,"") | G31: =IF(J31<>"rumus","1 x "&J31&" = "&J31,"rumus") -> rumus | H31: - | J31: =IF(I31<>"",IF(I31="a.Sebagai Ketua/wakil ketua pertahun",3,IF(I31="b.Sebagai Anggota pertahun",2,"")),"rumus") -> rumus
A32: 7 | B32: kegiatan | C32: - | E32: =IF(I32<>"",1,"") | F32: =IF(I32<>"",J32,"") | G32: =IF(J32<>"rumus","1 x "&J32&" = "&J32,"rumus") -> rumus | H32: - | J32: =IF(I32<>"",IF(I32="a.Sebagai Ketua/wakil ketua pertahun",3,IF(I32="b.Sebagai Anggota pertahun",2,"")),"rumus") -> rumus
A33: 8 | B33: kegiatan | C33: - | E33: =IF(I33<>"",1,"") | F33: =IF(I33<>"",J33,"") | G33: =IF(J33<>"rumus","1 x "&J33&" = "&J33,"rumus") -> rumus | H33: - | J33: =IF(I33<>"",IF(I33="a.Sebagai Ketua/wakil ketua pertahun",3,IF(I33="b.Sebagai Anggota pertahun",2,"")),"rumus") -> rumus
A34: 9 | B34: kegiatan | C34: - | E34: =IF(I34<>"",1,"") | F34: =IF(I34<>"",J34,"") | G34: =IF(J34<>"rumus","1 x "&J34&" = "&J34,"rumus") -> rumus | H34: - | J34: =IF(I34<>"",IF(I34="a.Sebagai Ketua/wakil ketua pertahun",3,IF(I34="b.Sebagai Anggota pertahun",2,"")),"rumus") -> rumus
A35: 10 | B35: kegiatan | C35: - | E35: =IF(I35<>"",1,"") | F35: =IF(I35<>"",J35,"") | G35: =IF(J35<>"rumus","1 x "&J35&" = "&J35,"rumus") -> rumus | H35: - | J35: =IF(I35<>"",IF(I35="a.Sebagai Ketua/wakil ketua pertahun",3,IF(I35="b.Sebagai Anggota pertahun",2,"")),"rumus") -> rumus
B36: Jumlah | G36: =SUM(J26:J35) -> 4
A37: B | B37: Menjadi anggota Panitia/Badan pada Lembaga Pemerintah
A38: 1 | B38: kegiatan | C38: - | E38: =IF(I38<>"",1,"") | F38: =IF(I38<>"",J38,"") | G38: =IF(J38<>"rumus","1 x "&J38&" = "&J38,"rumus") -> rumus | H38: - | J38: =IF(I38<>"",IF(I38="a.1).Panitia pusat sebagai Ketua/Wakil ketua",3,IF(I38="a.2).Panitia pusat sebagai Anggota",2,IF(I38="b.1).Panitia Daerah sebagai Ketua/Wakil Ketua",2,IF(I38="b.2).Panitia Daerah sebagai Anggota",1,"")))),"rumus") -> rumus
A39: 2 | B39: kegiatan | C39: - | E39: =IF(I39<>"",1,"") | F39: =IF(I39<>"",J39,"") | G39: =IF(J39<>"rumus","1 x "&J39&" = "&J39,"rumus") -> rumus | H39: - | J39: =IF(I39<>"",IF(I39="a.1).Panitia pusat sebagai Ketua/Wakil ketua",3,IF(I39="a.2).Panitia pusat sebagai Anggota",2,IF(I39="b.1).Panitia Daerah sebagai Ketua/Wakil Ketua",2,IF(I39="b.2).Panitia Daerah sebagai Anggota",1,"")))),"rumus") -> rumus
A40: 3 | B40: kegiatan | C40: - | E40: =IF(I40<>"",1,"") | F40: =IF(I40<>"",J40,"") | G40: =IF(J40<>"rumus","1 x "&J40&" = "&J40,"rumus") -> rumus | H40: - | J40: =IF(I40<>"",IF(I40="a.1).Panitia pusat sebagai Ketua/Wakil ketua",3,IF(I40="a.2).Panitia pusat sebagai Anggota",2,IF(I40="b.1).Panitia Daerah sebagai Ketua/Wakil Ketua",2,IF(I40="b.2).Panitia Daerah sebagai Anggota",1,"")))),"rumus") -> rumus
...

Sheet Reviewer Eksternal (LK&GB)1
A3: DAFTAR NILAI HASIL REVIEW PENELITIAN / PUBLIKASI KARYA ILMIAH
A4: DOSEN BIASA YANG DINILAI
A5: 1 | B5: NAMA | D5: Dr. Endang Soekamti, S.Si., M.Si | M5: Petunjuk
A6: 2 | B6: NIP/NIDN | D6: 00740196-1 / 0421097401 | N6: : Kotak berwarna KUNING untuk diisi (khusus profil atasan/yang memberi pernyataan)
A7: 3 | B7: JABATAN FUNGSIONAL | D7: Lektor Kepala | N7: : Kotak berwarna MERAH rumus yang akan otomatis terisi apabila Lampiran III sudah diisi
A8: 4 | B8: UNIT KERJA | D8: S1 Ilmu Komputasi, Fakultas Informatika, Universitas Telkom | N8: Untuk Row yang tidak diisi / dilewat mohon dihide, untuk field yang kurang, bisa copy Row kemudian Insert Row Created By : Nathaleo M. Apon.
A9: ANGKA KREDIT MENURUT PEER REVIEWER EKSTERNAL
A10: NO | B10: JUDUL KARYA ILMIAH | D10: NILAI MAKSIMAL | E10: JENIS KARYA ILMIAH | F10: Reviewer 1 (Prof. AAAA) | G10: Nilai Setelah Direview Prof. AAAA) | H10: Reviewer 2 (Prof. SSSSS) | I10: Nilai Setelah Direview Prof. SSSSS | J10: RATA-RATA PERSENTASE HASIL PEER REVIEW | K10: Nilai yang diusulkan setelah peer Review
A11: Jurnal Internasional
A12: 1 | B12: =IF('LAMPIRAN III DONE'!C29=0,"",'LAMPIRAN III DONE'!C29) -> aaa | D12: ='LAMPIRAN III DONE'!O29 -> 0 | E12: ='LAMPIRAN III DONE'!E29 -> Jurnal International Bereputasi | G12: =F12/100*D12 -> 0 | I12: =H12/100*D12 -> 0 | J12: =(F12+H12)/2 -> 0 | K12: =(J12/100)*D12 -> 0
B13: =IF('LAMPIRAN III DONE'!C30=0,"",'LAMPIRAN III DONE'!C30) -> aaa
A14: 2 | B14: =IF('LAMPIRAN III DONE'!C31=0,"",'LAMPIRAN III DONE'!C31) -> aaa | D14: ='LAMPIRAN III DONE'!O31 -> 0 | E14: ='LAMPIRAN III DONE'!E31 -> 0 | G14: =F14/100*D14 -> 0 | I14: =H14/100*D14 -> 0 | J14: =(F14+H14)/2 -> 0 | K14: =(J14/100)*D14 -> 0
B15: =IF('LAMPIRAN III DONE'!C32=0,"",'LAMPIRAN III DONE'!C32) -> aaa
A16: 3 | B16: =IF('LAMPIRAN III DONE'!C33=0,"",'LAMPIRAN III DONE'!C33) | D16: ='LAMPIRAN III DONE'!O33 -> 0 | E16: ='LAMPIRAN III DONE'!E33 -> 0 | G16: =F16/100*D16 -> 0 | I16: =H16/100*D16 -> 0 | J16: =(F16+H16)/2 -> 0 | K16: =(J16/100)*D16 -> 0
B17: =IF('LAMPIRAN III DONE'!C34=0,"",'LAMPIRAN III DONE'!C34)
A18: 4 | B18: =IF('LAMPIRAN III DONE'!C35=0,"",'LAMPIRAN III DONE'!C35) | D18: ='LAMPIRAN III DONE'!O35 -> 0 | E18: ='LAMPIRAN III DONE'!E35 -> 0 | G18: =F18/100*D18 -> 0 | I18: =H18/100*D18 -> 0 | J18: =(F18+H18)/2 -> 0 | K18: =(J18/100)*D18 -> 0
B19: =IF('LAMPIRAN III DONE'!C36=0,"",'LAMPIRAN III DONE'!C36)
A20: 5 | B20: =IF('LAMPIRAN III DONE'!C37=0,"",'LAMPIRAN III DONE'!C37) | D20: ='LAMPIRAN III DONE'!O37 -> 0 | E20: ='LAMPIRAN III DONE'!E37 -> 0 | G20: =F20/100*D20 -> 0 | I20: =H20/100*D20 -> 0 | J20: =(F20+H20)/2 -> 0 | K20: =(J20/100)*D20 -> 0
B21: =IF('LAMPIRAN III DONE'!C38=0,"",'LAMPIRAN III DONE'!C38)
A22: 6 | B22: =IF('LAMPIRAN III DONE'!C39=0,"",'LAMPIRAN III DONE'!C39) | D22: ='LAMPIRAN III DONE'!O39 -> 0 | E22: ='LAMPIRAN III DONE'!E39 -> 0 | G22: =F22/100*D22 -> 0 | I22: =H22/100*D22 -> 0 | J22: =(F22+H22)/2 -> 0 | K22: =(J22/100)*D22 -> 0
B23: =IF('LAMPIRAN III DONE'!C40=0,"",'LAMPIRAN III DONE'!C40)
